# Test Report v1.0.0

Date: 2024-08-02

## Test Run 1

### Test Results

========================================================================== test session starts ===========================================================================
platform win32 -- Python 3.11.4, pytest-8.2.2, pluggy-1.5.0 -- C:/ProgramData/anaconda3/envs/AG_Ex1/python.exe
cachedir: .pytest_cache
rootdir: c:/Agy/Programming/BelAInnovations/Projects/LLMFileManager/llm_file_operations
plugins: anyio-4.2.0
collecting ... collected 48 items

src/clipboard_monitor_unit_test.py::test_clipboard_monitor_initialization PASSED                                                                                    [  2%]
src/clipboard_monitor_unit_test.py::test_detect_format[LLMOP:/n  version: '1.0'-yaml] PASSED                                                                        [  4%]
src/clipboard_monitor_unit_test.py::test_detect_format[###LLMOP_START###/nSome content-custom] PASSED                                                               [  6%]
src/clipboard_monitor_unit_test.py::test_detect_format[Invalid content-None] PASSED                                                                                 [  8%]
src/clipboard_monitor_unit_test.py::test_start_monitoring_new_content PASSED                                                                                        [ 10%]
src/clipboard_monitor_unit_test.py::test_start_monitoring_error_handling PASSED                                                                                     [ 12%]
src/context_matcher_unit_test.py::test_initialization PASSED                                                                                                        [ 14%]
src/context_matcher_unit_test.py::test_find_context_lines_valid_contexts PASSED                                                                                     [ 16%]
src/context_matcher_unit_test.py::test_find_context_lines_start_only PASSED                                                                                         [ 18%]
src/context_matcher_unit_test.py::test_find_context_lines_no_contexts PASSED                                                                                        [ 20%]
src/context_matcher_unit_test.py::test_find_context_lines_start_not_found PASSED                                                                                    [ 22%]
src/context_matcher_unit_test.py::test_find_context_lines_end_not_found PASSED                                                                                      [ 25%]
src/context_matcher_unit_test.py::test_find_context_lines_multiline_contexts PASSED                                                                                 [ 27%]
src/context_matcher_unit_test.py::test_find_context_lines_beginning_of_file PASSED                                                                                  [ 29%]
src/context_matcher_unit_test.py::test_find_context_lines_end_of_file PASSED                                                                                        [ 31%]
src/context_matcher_unit_test.py::test_find_context_lines_overlapping_contexts PASSED                                                                               [ 33%]
src/context_matcher_unit_test.py::test_find_start_context PASSED                                                                                                    [ 35%]
src/context_matcher_unit_test.py::test_find_end_context PASSED                                                                                                      [ 37%]
src/context_matcher_unit_test.py::test_whitespace_handling PASSED                                                                                                   [ 39%]
src/context_matcher_unit_test.py::test_performance_large_files[100] PASSED                                                                                          [ 41%]
src/context_matcher_unit_test.py::test_performance_large_files[1000] PASSED                                                                                         [ 43%]
src/context_matcher_unit_test.py::test_performance_large_files[10000] PASSED                                                                                        [ 45%]
src/error_handler_unit_test.py::test_error_handler_initialization PASSED                                                                                            [ 47%]
src/error_handler_unit_test.py::test_handle_standard_exception PASSED                                                                                               [ 50%]
src/error_handler_unit_test.py::test_handle_custom_exception PASSED                                                                                                 [ 52%]
src/error_handler_unit_test.py::test_handle_system_exception PASSED                                                                                                 [ 54%]
src/error_handler_unit_test.py::test_handle_error_simple_message PASSED                                                                                             [ 56%]
src/error_handler_unit_test.py::test_handle_error_multiline_message PASSED                                                                                          [ 58%]
src/error_handler_unit_test.py::test_handle_error_special_characters PASSED                                                                                         [ 60%]
src/error_handler_unit_test.py::test_logging_level PASSED                                                                                                           [ 62%]
src/error_handler_unit_test.py::test_exception_and_traceback_logged PASSED                                                                                          [ 64%]
src/error_handler_unit_test.py::test_logging_behavior_different_levels[DEBUG] PASSED                                                                                [ 66%]
src/error_handler_unit_test.py::test_logging_behavior_different_levels[INFO] PASSED                                                                                 [ 68%]
src/error_handler_unit_test.py::test_logging_behavior_different_levels[WARNING] PASSED                                                                              [ 70%]
src/error_handler_unit_test.py::test_logging_behavior_different_levels[ERROR] PASSED                                                                                [ 72%]
src/error_handler_unit_test.py::test_logging_behavior_different_levels[CRITICAL] PASSED                                                                             [ 75%]
src/file_operations_unit_test.py::test_create_file FAILED                                                                                                           [ 77%]
src/file_operations_unit_test.py::test_create_folder PASSED                                                                                                         [ 79%]
src/file_operations_unit_test.py::test_delete_file PASSED                                                                                                           [ 81%]
src/file_operations_unit_test.py::test_modify_file_replace FAILED                                                                                                   [ 83%]
src/file_operations_unit_test.py::test_modify_file_insert FAILED                                                                                                    [ 85%]
src/file_operations_unit_test.py::test_execute_file_size_limit FAILED                                                                                               [ 87%]
src/file_operations_unit_test.py::test_execute_invalid_file_extension PASSED                                                                                        [ 89%]
src/file_operations_unit_test.py::test_delete_nonexistent_file PASSED                                                                                               [ 91%]
src/file_operations_unit_test.py::test_create_folder_permission_error PASSED                                                                                        [ 93%]
src/file_operations_unit_test.py::test_execute_unknown_action PASSED                                                                                                [ 95%]
src/file_operations_unit_test.py::test_modify_file_delete FAILED                                                                                                    [ 97%]
src/file_operations_unit_test.py::test_delete_folder FAILED                                                                                                         [100%]

================================================================================ FAILURES ================================================================================
____________________________________________________________________________ test_create_file ____________________________________________________________________________
src/file_operations_unit_test.py:35: in test_create_file
    mock_open().write.assert_called_once_with('content')
C:/ProgramData/anaconda3/envs/AG_Ex1/Lib/unittest/mock.py:950: in assert_called_once_with
    raise AssertionError(msg)
E   AssertionError: Expected 'write' to be called once. Called 0 times.
--------------------------------------------------------------------------- Captured log call ----------------------------------------------------------------------------
ERROR    file_operations:file_operations.py:67 Error creating file: 'Mock' object does not support the context manager protocol
Traceback (most recent call last):
  File "c:/Agy/Programming/BelAInnovations/Projects/LLMFileManager/llm_file_operations/src/file_operations.py", line 60, in create_file
    with open(file_path, 'w', newline='') as f:
TypeError: 'Mock' object does not support the context manager protocol
________________________________________________________________________ test_modify_file_replace ________________________________________________________________________
src/file_operations_unit_test.py:52: in test_modify_file_replace
    mock_open.return_value.__enter__.return_value.readlines.return_value = mock_file_content
C:/ProgramData/anaconda3/envs/AG_Ex1/Lib/unittest/mock.py:655: in __getattr__
    raise AttributeError(name)
E   AttributeError: __enter__
________________________________________________________________________ test_modify_file_insert _________________________________________________________________________
src/file_operations_unit_test.py:72: in test_modify_file_insert
    mock_open.return_value.__enter__.return_value.readlines.return_value = mock_file_content
C:/ProgramData/anaconda3/envs/AG_Ex1/Lib/unittest/mock.py:655: in __getattr__
    raise AttributeError(name)
E   AttributeError: __enter__
______________________________________________________________________ test_execute_file_size_limit ______________________________________________________________________
src/file_operations_unit_test.py:100: in test_execute_file_size_limit
    mock_error_handler.handle_error.assert_called_once_with("File size exceeds maximum allowed size: large_file.txt")
C:/ProgramData/anaconda3/envs/AG_Ex1/Lib/unittest/mock.py:951: in assert_called_once_with
    return self.assert_called_with(*args, **kwargs)
C:/ProgramData/anaconda3/envs/AG_Ex1/Lib/unittest/mock.py:939: in assert_called_with
    raise AssertionError(_error_message()) from cause
E   AssertionError: expected call not found.
E   Expected: handle_error('File size exceeds maximum allowed size: large_file.txt')
E   Actual: handle_error('File size exceeds maximum allowed size: .//large_file.txt')
________________________________________________________________________ test_modify_file_delete _________________________________________________________________________
src/file_operations_unit_test.py:134: in test_modify_file_delete
    mock_open.return_value.__enter__.return_value.readlines.return_value = mock_file_content
C:/ProgramData/anaconda3/envs/AG_Ex1/Lib/unittest/mock.py:655: in __getattr__
    raise AttributeError(name)
E   AttributeError: __enter__
___________________________________________________________________________ test_delete_folder ___________________________________________________________________________
src/file_operations_unit_test.py:154: in test_delete_folder
    mock_rmtree.assert_called_once_with('test/folder')
C:/ProgramData/anaconda3/envs/AG_Ex1/Lib/unittest/mock.py:950: in assert_called_once_with
    raise AssertionError(msg)
E   AssertionError: Expected 'rmtree' to be called once. Called 0 times.
--------------------------------------------------------------------------- Captured log call ----------------------------------------------------------------------------
ERROR    file_operations:file_operations.py:101 Error deleting folder: name 'shutil' is not defined
Traceback (most recent call last):
  File "c:/Agy/Programming/BelAInnovations/Projects/LLMFileManager/llm_file_operations/src/file_operations.py", line 96, in delete_folder
    shutil.rmtree(folder_path)
    ^^^^^^
NameError: name 'shutil' is not defined
======================================================================== short test summary info =========================================================================
FAILED src/file_operations_unit_test.py::test_create_file - AssertionError: Expected 'write' to be called once. Called 0 times.
FAILED src/file_operations_unit_test.py::test_modify_file_replace - AttributeError: __enter__
FAILED src/file_operations_unit_test.py::test_modify_file_insert - AttributeError: __enter__
FAILED src/file_operations_unit_test.py::test_execute_file_size_limit - AssertionError: expected call not found.
FAILED src/file_operations_unit_test.py::test_modify_file_delete - AttributeError: __enter__
FAILED src/file_operations_unit_test.py::test_delete_folder - AssertionError: Expected 'rmtree' to be called once. Called 0 times.
====================================================================== 6 failed, 42 passed in 2.23s ======================================================================

Exit Code: 1

================================================================================

## Test Run 2

### Test Results

========================================================================== test session starts ===========================================================================
platform win32 -- Python 3.11.4, pytest-8.2.2, pluggy-1.5.0 -- C:/ProgramData/anaconda3/envs/AG_Ex1/python.exe
cachedir: .pytest_cache
rootdir: c:/Agy/Programming/BelAInnovations/Projects/LLMFileManager/llm_file_operations
plugins: anyio-4.2.0
collecting ... collected 48 items

src/clipboard_monitor_unit_test.py::test_clipboard_monitor_initialization PASSED                                                                                    [  2%]
src/clipboard_monitor_unit_test.py::test_detect_format[LLMOP:/n  version: '1.0'-yaml] PASSED                                                                        [  4%]
src/clipboard_monitor_unit_test.py::test_detect_format[###LLMOP_START###/nSome content-custom] PASSED                                                               [  6%]
src/clipboard_monitor_unit_test.py::test_detect_format[Invalid content-None] PASSED                                                                                 [  8%]
src/clipboard_monitor_unit_test.py::test_start_monitoring_new_content PASSED                                                                                        [ 10%]
src/clipboard_monitor_unit_test.py::test_start_monitoring_error_handling PASSED                                                                                     [ 12%]
src/context_matcher_unit_test.py::test_initialization PASSED                                                                                                        [ 14%]
src/context_matcher_unit_test.py::test_find_context_lines_valid_contexts PASSED                                                                                     [ 16%]
src/context_matcher_unit_test.py::test_find_context_lines_start_only PASSED                                                                                         [ 18%]
src/context_matcher_unit_test.py::test_find_context_lines_no_contexts PASSED                                                                                        [ 20%]
src/context_matcher_unit_test.py::test_find_context_lines_start_not_found PASSED                                                                                    [ 22%]
src/context_matcher_unit_test.py::test_find_context_lines_end_not_found PASSED                                                                                      [ 25%]
src/context_matcher_unit_test.py::test_find_context_lines_multiline_contexts PASSED                                                                                 [ 27%]
src/context_matcher_unit_test.py::test_find_context_lines_beginning_of_file PASSED                                                                                  [ 29%]
src/context_matcher_unit_test.py::test_find_context_lines_end_of_file PASSED                                                                                        [ 31%]
src/context_matcher_unit_test.py::test_find_context_lines_overlapping_contexts PASSED                                                                               [ 33%]
src/context_matcher_unit_test.py::test_find_start_context PASSED                                                                                                    [ 35%]
src/context_matcher_unit_test.py::test_find_end_context PASSED                                                                                                      [ 37%]
src/context_matcher_unit_test.py::test_whitespace_handling PASSED                                                                                                   [ 39%]
src/context_matcher_unit_test.py::test_performance_large_files[100] PASSED                                                                                          [ 41%]
src/context_matcher_unit_test.py::test_performance_large_files[1000] PASSED                                                                                         [ 43%]
src/context_matcher_unit_test.py::test_performance_large_files[10000] PASSED                                                                                        [ 45%]
src/error_handler_unit_test.py::test_error_handler_initialization PASSED                                                                                            [ 47%]
src/error_handler_unit_test.py::test_handle_standard_exception PASSED                                                                                               [ 50%]
src/error_handler_unit_test.py::test_handle_custom_exception PASSED                                                                                                 [ 52%]
src/error_handler_unit_test.py::test_handle_system_exception PASSED                                                                                                 [ 54%]
src/error_handler_unit_test.py::test_handle_error_simple_message PASSED                                                                                             [ 56%]
src/error_handler_unit_test.py::test_handle_error_multiline_message PASSED                                                                                          [ 58%]
src/error_handler_unit_test.py::test_handle_error_special_characters PASSED                                                                                         [ 60%]
src/error_handler_unit_test.py::test_logging_level PASSED                                                                                                           [ 62%]
src/error_handler_unit_test.py::test_exception_and_traceback_logged PASSED                                                                                          [ 64%]
src/error_handler_unit_test.py::test_logging_behavior_different_levels[DEBUG] PASSED                                                                                [ 66%]
src/error_handler_unit_test.py::test_logging_behavior_different_levels[INFO] PASSED                                                                                 [ 68%]
src/error_handler_unit_test.py::test_logging_behavior_different_levels[WARNING] PASSED                                                                              [ 70%]
src/error_handler_unit_test.py::test_logging_behavior_different_levels[ERROR] PASSED                                                                                [ 72%]
src/error_handler_unit_test.py::test_logging_behavior_different_levels[CRITICAL] PASSED                                                                             [ 75%]
src/file_operations_unit_test.py::test_create_file FAILED                                                                                                           [ 77%]
src/file_operations_unit_test.py::test_create_folder PASSED                                                                                                         [ 79%]
src/file_operations_unit_test.py::test_delete_file PASSED                                                                                                           [ 81%]
src/file_operations_unit_test.py::test_modify_file_replace FAILED                                                                                                   [ 83%]
src/file_operations_unit_test.py::test_modify_file_insert FAILED                                                                                                    [ 85%]
src/file_operations_unit_test.py::test_execute_file_size_limit FAILED                                                                                               [ 87%]
src/file_operations_unit_test.py::test_execute_invalid_file_extension PASSED                                                                                        [ 89%]
src/file_operations_unit_test.py::test_delete_nonexistent_file PASSED                                                                                               [ 91%]
src/file_operations_unit_test.py::test_create_folder_permission_error PASSED                                                                                        [ 93%]
src/file_operations_unit_test.py::test_execute_unknown_action PASSED                                                                                                [ 95%]
src/file_operations_unit_test.py::test_modify_file_delete FAILED                                                                                                    [ 97%]
src/file_operations_unit_test.py::test_delete_folder FAILED                                                                                                         [100%]

================================================================================ FAILURES ================================================================================
____________________________________________________________________________ test_create_file ____________________________________________________________________________
src/file_operations_unit_test.py:35: in test_create_file
    mock_open().write.assert_called_once_with('content')
C:/ProgramData/anaconda3/envs/AG_Ex1/Lib/unittest/mock.py:950: in assert_called_once_with
    raise AssertionError(msg)
E   AssertionError: Expected 'write' to be called once. Called 0 times.
--------------------------------------------------------------------------- Captured log call ----------------------------------------------------------------------------
ERROR    file_operations:file_operations.py:67 Error creating file: 'Mock' object does not support the context manager protocol
Traceback (most recent call last):
  File "c:/Agy/Programming/BelAInnovations/Projects/LLMFileManager/llm_file_operations/src/file_operations.py", line 60, in create_file
    with open(file_path, 'w', newline='') as f:
TypeError: 'Mock' object does not support the context manager protocol
________________________________________________________________________ test_modify_file_replace ________________________________________________________________________
src/file_operations_unit_test.py:52: in test_modify_file_replace
    mock_open.return_value.__enter__.return_value.readlines.return_value = mock_file_content
C:/ProgramData/anaconda3/envs/AG_Ex1/Lib/unittest/mock.py:655: in __getattr__
    raise AttributeError(name)
E   AttributeError: __enter__
________________________________________________________________________ test_modify_file_insert _________________________________________________________________________
src/file_operations_unit_test.py:72: in test_modify_file_insert
    mock_open.return_value.__enter__.return_value.readlines.return_value = mock_file_content
C:/ProgramData/anaconda3/envs/AG_Ex1/Lib/unittest/mock.py:655: in __getattr__
    raise AttributeError(name)
E   AttributeError: __enter__
______________________________________________________________________ test_execute_file_size_limit ______________________________________________________________________
src/file_operations_unit_test.py:100: in test_execute_file_size_limit
    mock_error_handler.handle_error.assert_called_once_with("File size exceeds maximum allowed size: large_file.txt")
C:/ProgramData/anaconda3/envs/AG_Ex1/Lib/unittest/mock.py:951: in assert_called_once_with
    return self.assert_called_with(*args, **kwargs)
C:/ProgramData/anaconda3/envs/AG_Ex1/Lib/unittest/mock.py:939: in assert_called_with
    raise AssertionError(_error_message()) from cause
E   AssertionError: expected call not found.
E   Expected: handle_error('File size exceeds maximum allowed size: large_file.txt')
E   Actual: handle_error('File size exceeds maximum allowed size: .//large_file.txt')
________________________________________________________________________ test_modify_file_delete _________________________________________________________________________
src/file_operations_unit_test.py:134: in test_modify_file_delete
    mock_open.return_value.__enter__.return_value.readlines.return_value = mock_file_content
C:/ProgramData/anaconda3/envs/AG_Ex1/Lib/unittest/mock.py:655: in __getattr__
    raise AttributeError(name)
E   AttributeError: __enter__
___________________________________________________________________________ test_delete_folder ___________________________________________________________________________
src/file_operations_unit_test.py:154: in test_delete_folder
    mock_rmtree.assert_called_once_with('test/folder')
C:/ProgramData/anaconda3/envs/AG_Ex1/Lib/unittest/mock.py:950: in assert_called_once_with
    raise AssertionError(msg)
E   AssertionError: Expected 'rmtree' to be called once. Called 0 times.
--------------------------------------------------------------------------- Captured log call ----------------------------------------------------------------------------
ERROR    file_operations:file_operations.py:101 Error deleting folder: name 'shutil' is not defined
Traceback (most recent call last):
  File "c:/Agy/Programming/BelAInnovations/Projects/LLMFileManager/llm_file_operations/src/file_operations.py", line 96, in delete_folder
    shutil.rmtree(folder_path)
    ^^^^^^
NameError: name 'shutil' is not defined
======================================================================== short test summary info =========================================================================
FAILED src/file_operations_unit_test.py::test_create_file - AssertionError: Expected 'write' to be called once. Called 0 times.
FAILED src/file_operations_unit_test.py::test_modify_file_replace - AttributeError: __enter__
FAILED src/file_operations_unit_test.py::test_modify_file_insert - AttributeError: __enter__
FAILED src/file_operations_unit_test.py::test_execute_file_size_limit - AssertionError: expected call not found.
FAILED src/file_operations_unit_test.py::test_modify_file_delete - AttributeError: __enter__
FAILED src/file_operations_unit_test.py::test_delete_folder - AssertionError: Expected 'rmtree' to be called once. Called 0 times.
====================================================================== 6 failed, 42 passed in 1.71s ======================================================================

Exit Code: 1

================================================================================

## Test Run 3

### Test Results

========================================================================== test session starts ===========================================================================
platform win32 -- Python 3.11.4, pytest-8.2.2, pluggy-1.5.0 -- C:/ProgramData/anaconda3/envs/AG_Ex1/python.exe
cachedir: .pytest_cache
rootdir: c:/Agy/Programming/BelAInnovations/Projects/LLMFileManager/llm_file_operations
plugins: anyio-4.2.0
collecting ... collected 48 items

src/clipboard_monitor_unit_test.py::test_clipboard_monitor_initialization PASSED                                                                                    [  2%]
src/clipboard_monitor_unit_test.py::test_detect_format[LLMOP:/n  version: '1.0'-yaml] PASSED                                                                        [  4%]
src/clipboard_monitor_unit_test.py::test_detect_format[###LLMOP_START###/nSome content-custom] PASSED                                                               [  6%]
src/clipboard_monitor_unit_test.py::test_detect_format[Invalid content-None] PASSED                                                                                 [  8%]
src/clipboard_monitor_unit_test.py::test_start_monitoring_new_content PASSED                                                                                        [ 10%]
src/clipboard_monitor_unit_test.py::test_start_monitoring_error_handling PASSED                                                                                     [ 12%]
src/context_matcher_unit_test.py::test_initialization PASSED                                                                                                        [ 14%]
src/context_matcher_unit_test.py::test_find_context_lines_valid_contexts PASSED                                                                                     [ 16%]
src/context_matcher_unit_test.py::test_find_context_lines_start_only PASSED                                                                                         [ 18%]
src/context_matcher_unit_test.py::test_find_context_lines_no_contexts PASSED                                                                                        [ 20%]
src/context_matcher_unit_test.py::test_find_context_lines_start_not_found PASSED                                                                                    [ 22%]
src/context_matcher_unit_test.py::test_find_context_lines_end_not_found PASSED                                                                                      [ 25%]
src/context_matcher_unit_test.py::test_find_context_lines_multiline_contexts PASSED                                                                                 [ 27%]
src/context_matcher_unit_test.py::test_find_context_lines_beginning_of_file PASSED                                                                                  [ 29%]
src/context_matcher_unit_test.py::test_find_context_lines_end_of_file PASSED                                                                                        [ 31%]
src/context_matcher_unit_test.py::test_find_context_lines_overlapping_contexts PASSED                                                                               [ 33%]
src/context_matcher_unit_test.py::test_find_start_context PASSED                                                                                                    [ 35%]
src/context_matcher_unit_test.py::test_find_end_context PASSED                                                                                                      [ 37%]
src/context_matcher_unit_test.py::test_whitespace_handling PASSED                                                                                                   [ 39%]
src/context_matcher_unit_test.py::test_performance_large_files[100] PASSED                                                                                          [ 41%]
src/context_matcher_unit_test.py::test_performance_large_files[1000] PASSED                                                                                         [ 43%]
src/context_matcher_unit_test.py::test_performance_large_files[10000] PASSED                                                                                        [ 45%]
src/error_handler_unit_test.py::test_error_handler_initialization PASSED                                                                                            [ 47%]
src/error_handler_unit_test.py::test_handle_standard_exception PASSED                                                                                               [ 50%]
src/error_handler_unit_test.py::test_handle_custom_exception PASSED                                                                                                 [ 52%]
src/error_handler_unit_test.py::test_handle_system_exception PASSED                                                                                                 [ 54%]
src/error_handler_unit_test.py::test_handle_error_simple_message PASSED                                                                                             [ 56%]
src/error_handler_unit_test.py::test_handle_error_multiline_message PASSED                                                                                          [ 58%]
src/error_handler_unit_test.py::test_handle_error_special_characters PASSED                                                                                         [ 60%]
src/error_handler_unit_test.py::test_logging_level PASSED                                                                                                           [ 62%]
src/error_handler_unit_test.py::test_exception_and_traceback_logged PASSED                                                                                          [ 64%]
src/error_handler_unit_test.py::test_logging_behavior_different_levels[DEBUG] PASSED                                                                                [ 66%]
src/error_handler_unit_test.py::test_logging_behavior_different_levels[INFO] PASSED                                                                                 [ 68%]
src/error_handler_unit_test.py::test_logging_behavior_different_levels[WARNING] PASSED                                                                              [ 70%]
src/error_handler_unit_test.py::test_logging_behavior_different_levels[ERROR] PASSED                                                                                [ 72%]
src/error_handler_unit_test.py::test_logging_behavior_different_levels[CRITICAL] PASSED                                                                             [ 75%]
src/file_operations_unit_test.py::test_create_file FAILED                                                                                                           [ 77%]
src/file_operations_unit_test.py::test_create_folder PASSED                                                                                                         [ 79%]
src/file_operations_unit_test.py::test_delete_file PASSED                                                                                                           [ 81%]
src/file_operations_unit_test.py::test_modify_file_replace FAILED                                                                                                   [ 83%]
src/file_operations_unit_test.py::test_modify_file_insert FAILED                                                                                                    [ 85%]
src/file_operations_unit_test.py::test_execute_file_size_limit FAILED                                                                                               [ 87%]
src/file_operations_unit_test.py::test_execute_invalid_file_extension PASSED                                                                                        [ 89%]
src/file_operations_unit_test.py::test_delete_nonexistent_file PASSED                                                                                               [ 91%]
src/file_operations_unit_test.py::test_create_folder_permission_error PASSED                                                                                        [ 93%]
src/file_operations_unit_test.py::test_execute_unknown_action PASSED                                                                                                [ 95%]
src/file_operations_unit_test.py::test_modify_file_delete FAILED                                                                                                    [ 97%]
src/file_operations_unit_test.py::test_delete_folder FAILED                                                                                                         [100%]

================================================================================ FAILURES ================================================================================
____________________________________________________________________________ test_create_file ____________________________________________________________________________
src/file_operations_unit_test.py:35: in test_create_file
    mock_open().write.assert_called_once_with('content')
C:/ProgramData/anaconda3/envs/AG_Ex1/Lib/unittest/mock.py:950: in assert_called_once_with
    raise AssertionError(msg)
E   AssertionError: Expected 'write' to be called once. Called 0 times.
--------------------------------------------------------------------------- Captured log call ----------------------------------------------------------------------------
ERROR    file_operations:file_operations.py:67 Error creating file: 'Mock' object does not support the context manager protocol
Traceback (most recent call last):
  File "c:/Agy/Programming/BelAInnovations/Projects/LLMFileManager/llm_file_operations/src/file_operations.py", line 60, in create_file
    with open(file_path, 'w', newline='') as f:
TypeError: 'Mock' object does not support the context manager protocol
________________________________________________________________________ test_modify_file_replace ________________________________________________________________________
src/file_operations_unit_test.py:52: in test_modify_file_replace
    mock_open.return_value.__enter__.return_value.readlines.return_value = mock_file_content
C:/ProgramData/anaconda3/envs/AG_Ex1/Lib/unittest/mock.py:655: in __getattr__
    raise AttributeError(name)
E   AttributeError: __enter__
________________________________________________________________________ test_modify_file_insert _________________________________________________________________________
src/file_operations_unit_test.py:72: in test_modify_file_insert
    mock_open.return_value.__enter__.return_value.readlines.return_value = mock_file_content
C:/ProgramData/anaconda3/envs/AG_Ex1/Lib/unittest/mock.py:655: in __getattr__
    raise AttributeError(name)
E   AttributeError: __enter__
______________________________________________________________________ test_execute_file_size_limit ______________________________________________________________________
src/file_operations_unit_test.py:100: in test_execute_file_size_limit
    mock_error_handler.handle_error.assert_called_once_with("File size exceeds maximum allowed size: large_file.txt")
C:/ProgramData/anaconda3/envs/AG_Ex1/Lib/unittest/mock.py:951: in assert_called_once_with
    return self.assert_called_with(*args, **kwargs)
C:/ProgramData/anaconda3/envs/AG_Ex1/Lib/unittest/mock.py:939: in assert_called_with
    raise AssertionError(_error_message()) from cause
E   AssertionError: expected call not found.
E   Expected: handle_error('File size exceeds maximum allowed size: large_file.txt')
E   Actual: handle_error('File size exceeds maximum allowed size: .//large_file.txt')
________________________________________________________________________ test_modify_file_delete _________________________________________________________________________
src/file_operations_unit_test.py:134: in test_modify_file_delete
    mock_open.return_value.__enter__.return_value.readlines.return_value = mock_file_content
C:/ProgramData/anaconda3/envs/AG_Ex1/Lib/unittest/mock.py:655: in __getattr__
    raise AttributeError(name)
E   AttributeError: __enter__
___________________________________________________________________________ test_delete_folder ___________________________________________________________________________
src/file_operations_unit_test.py:154: in test_delete_folder
    mock_rmtree.assert_called_once_with('test/folder')
C:/ProgramData/anaconda3/envs/AG_Ex1/Lib/unittest/mock.py:950: in assert_called_once_with
    raise AssertionError(msg)
E   AssertionError: Expected 'rmtree' to be called once. Called 0 times.
--------------------------------------------------------------------------- Captured log call ----------------------------------------------------------------------------
ERROR    file_operations:file_operations.py:101 Error deleting folder: name 'shutil' is not defined
Traceback (most recent call last):
  File "c:/Agy/Programming/BelAInnovations/Projects/LLMFileManager/llm_file_operations/src/file_operations.py", line 96, in delete_folder
    shutil.rmtree(folder_path)
    ^^^^^^
NameError: name 'shutil' is not defined
======================================================================== short test summary info =========================================================================
FAILED src/file_operations_unit_test.py::test_create_file - AssertionError: Expected 'write' to be called once. Called 0 times.
FAILED src/file_operations_unit_test.py::test_modify_file_replace - AttributeError: __enter__
FAILED src/file_operations_unit_test.py::test_modify_file_insert - AttributeError: __enter__
FAILED src/file_operations_unit_test.py::test_execute_file_size_limit - AssertionError: expected call not found.
FAILED src/file_operations_unit_test.py::test_modify_file_delete - AttributeError: __enter__
FAILED src/file_operations_unit_test.py::test_delete_folder - AssertionError: Expected 'rmtree' to be called once. Called 0 times.
====================================================================== 6 failed, 42 passed in 1.77s ======================================================================

Exit Code: 1

================================================================================

## Test Run 4

### Test Results

========================================================================== test session starts ===========================================================================
platform win32 -- Python 3.11.4, pytest-8.2.2, pluggy-1.5.0 -- C:/ProgramData/anaconda3/envs/AG_Ex1/python.exe
cachedir: .pytest_cache
rootdir: c:/Agy/Programming/BelAInnovations/Projects/LLMFileManager/llm_file_operations
plugins: anyio-4.2.0
collecting ... collected 48 items

src/clipboard_monitor_unit_test.py::test_clipboard_monitor_initialization PASSED                                                                                    [  2%]
src/clipboard_monitor_unit_test.py::test_detect_format[LLMOP:/n  version: '1.0'-yaml] PASSED                                                                        [  4%]
src/clipboard_monitor_unit_test.py::test_detect_format[###LLMOP_START###/nSome content-custom] PASSED                                                               [  6%]
src/clipboard_monitor_unit_test.py::test_detect_format[Invalid content-None] PASSED                                                                                 [  8%]
src/clipboard_monitor_unit_test.py::test_start_monitoring_new_content PASSED                                                                                        [ 10%]
src/clipboard_monitor_unit_test.py::test_start_monitoring_error_handling PASSED                                                                                     [ 12%]
src/context_matcher_unit_test.py::test_initialization PASSED                                                                                                        [ 14%]
src/context_matcher_unit_test.py::test_find_context_lines_valid_contexts PASSED                                                                                     [ 16%]
src/context_matcher_unit_test.py::test_find_context_lines_start_only PASSED                                                                                         [ 18%]
src/context_matcher_unit_test.py::test_find_context_lines_no_contexts PASSED                                                                                        [ 20%]
src/context_matcher_unit_test.py::test_find_context_lines_start_not_found PASSED                                                                                    [ 22%]
src/context_matcher_unit_test.py::test_find_context_lines_end_not_found PASSED                                                                                      [ 25%]
src/context_matcher_unit_test.py::test_find_context_lines_multiline_contexts PASSED                                                                                 [ 27%]
src/context_matcher_unit_test.py::test_find_context_lines_beginning_of_file PASSED                                                                                  [ 29%]
src/context_matcher_unit_test.py::test_find_context_lines_end_of_file PASSED                                                                                        [ 31%]
src/context_matcher_unit_test.py::test_find_context_lines_overlapping_contexts PASSED                                                                               [ 33%]
src/context_matcher_unit_test.py::test_find_start_context PASSED                                                                                                    [ 35%]
src/context_matcher_unit_test.py::test_find_end_context PASSED                                                                                                      [ 37%]
src/context_matcher_unit_test.py::test_whitespace_handling PASSED                                                                                                   [ 39%]
src/context_matcher_unit_test.py::test_performance_large_files[100] PASSED                                                                                          [ 41%]
src/context_matcher_unit_test.py::test_performance_large_files[1000] PASSED                                                                                         [ 43%]
src/context_matcher_unit_test.py::test_performance_large_files[10000] PASSED                                                                                        [ 45%]
src/error_handler_unit_test.py::test_error_handler_initialization PASSED                                                                                            [ 47%]
src/error_handler_unit_test.py::test_handle_standard_exception PASSED                                                                                               [ 50%]
src/error_handler_unit_test.py::test_handle_custom_exception PASSED                                                                                                 [ 52%]
src/error_handler_unit_test.py::test_handle_system_exception PASSED                                                                                                 [ 54%]
src/error_handler_unit_test.py::test_handle_error_simple_message PASSED                                                                                             [ 56%]
src/error_handler_unit_test.py::test_handle_error_multiline_message PASSED                                                                                          [ 58%]
src/error_handler_unit_test.py::test_handle_error_special_characters PASSED                                                                                         [ 60%]
src/error_handler_unit_test.py::test_logging_level PASSED                                                                                                           [ 62%]
src/error_handler_unit_test.py::test_exception_and_traceback_logged PASSED                                                                                          [ 64%]
src/error_handler_unit_test.py::test_logging_behavior_different_levels[DEBUG] PASSED                                                                                [ 66%]
src/error_handler_unit_test.py::test_logging_behavior_different_levels[INFO] PASSED                                                                                 [ 68%]
src/error_handler_unit_test.py::test_logging_behavior_different_levels[WARNING] PASSED                                                                              [ 70%]
src/error_handler_unit_test.py::test_logging_behavior_different_levels[ERROR] PASSED                                                                                [ 72%]
src/error_handler_unit_test.py::test_logging_behavior_different_levels[CRITICAL] PASSED                                                                             [ 75%]
src/file_operations_unit_test.py::test_create_file FAILED                                                                                                           [ 77%]
src/file_operations_unit_test.py::test_create_folder PASSED                                                                                                         [ 79%]
src/file_operations_unit_test.py::test_delete_file PASSED                                                                                                           [ 81%]
src/file_operations_unit_test.py::test_modify_file_replace FAILED                                                                                                   [ 83%]
src/file_operations_unit_test.py::test_modify_file_insert FAILED                                                                                                    [ 85%]
src/file_operations_unit_test.py::test_execute_file_size_limit FAILED                                                                                               [ 87%]
src/file_operations_unit_test.py::test_execute_invalid_file_extension PASSED                                                                                        [ 89%]
src/file_operations_unit_test.py::test_delete_nonexistent_file PASSED                                                                                               [ 91%]
src/file_operations_unit_test.py::test_create_folder_permission_error PASSED                                                                                        [ 93%]
src/file_operations_unit_test.py::test_execute_unknown_action PASSED                                                                                                [ 95%]
src/file_operations_unit_test.py::test_modify_file_delete FAILED                                                                                                    [ 97%]
src/file_operations_unit_test.py::test_delete_folder FAILED                                                                                                         [100%]

================================================================================ FAILURES ================================================================================
____________________________________________________________________________ test_create_file ____________________________________________________________________________
src/file_operations_unit_test.py:35: in test_create_file
    mock_open().write.assert_called_once_with('content')
C:/ProgramData/anaconda3/envs/AG_Ex1/Lib/unittest/mock.py:950: in assert_called_once_with
    raise AssertionError(msg)
E   AssertionError: Expected 'write' to be called once. Called 0 times.
--------------------------------------------------------------------------- Captured log call ----------------------------------------------------------------------------
ERROR    file_operations:file_operations.py:67 Error creating file: 'Mock' object does not support the context manager protocol
Traceback (most recent call last):
  File "c:/Agy/Programming/BelAInnovations/Projects/LLMFileManager/llm_file_operations/src/file_operations.py", line 60, in create_file
    with open(file_path, 'w', newline='') as f:
TypeError: 'Mock' object does not support the context manager protocol
________________________________________________________________________ test_modify_file_replace ________________________________________________________________________
src/file_operations_unit_test.py:52: in test_modify_file_replace
    mock_open.return_value.__enter__.return_value.readlines.return_value = mock_file_content
C:/ProgramData/anaconda3/envs/AG_Ex1/Lib/unittest/mock.py:655: in __getattr__
    raise AttributeError(name)
E   AttributeError: __enter__
________________________________________________________________________ test_modify_file_insert _________________________________________________________________________
src/file_operations_unit_test.py:72: in test_modify_file_insert
    mock_open.return_value.__enter__.return_value.readlines.return_value = mock_file_content
C:/ProgramData/anaconda3/envs/AG_Ex1/Lib/unittest/mock.py:655: in __getattr__
    raise AttributeError(name)
E   AttributeError: __enter__
______________________________________________________________________ test_execute_file_size_limit ______________________________________________________________________
src/file_operations_unit_test.py:100: in test_execute_file_size_limit
    mock_error_handler.handle_error.assert_called_once_with("File size exceeds maximum allowed size: large_file.txt")
C:/ProgramData/anaconda3/envs/AG_Ex1/Lib/unittest/mock.py:951: in assert_called_once_with
    return self.assert_called_with(*args, **kwargs)
C:/ProgramData/anaconda3/envs/AG_Ex1/Lib/unittest/mock.py:939: in assert_called_with
    raise AssertionError(_error_message()) from cause
E   AssertionError: expected call not found.
E   Expected: handle_error('File size exceeds maximum allowed size: large_file.txt')
E   Actual: handle_error('File size exceeds maximum allowed size: .//large_file.txt')
________________________________________________________________________ test_modify_file_delete _________________________________________________________________________
src/file_operations_unit_test.py:134: in test_modify_file_delete
    mock_open.return_value.__enter__.return_value.readlines.return_value = mock_file_content
C:/ProgramData/anaconda3/envs/AG_Ex1/Lib/unittest/mock.py:655: in __getattr__
    raise AttributeError(name)
E   AttributeError: __enter__
___________________________________________________________________________ test_delete_folder ___________________________________________________________________________
src/file_operations_unit_test.py:154: in test_delete_folder
    mock_rmtree.assert_called_once_with('test/folder')
C:/ProgramData/anaconda3/envs/AG_Ex1/Lib/unittest/mock.py:950: in assert_called_once_with
    raise AssertionError(msg)
E   AssertionError: Expected 'rmtree' to be called once. Called 0 times.
--------------------------------------------------------------------------- Captured log call ----------------------------------------------------------------------------
ERROR    file_operations:file_operations.py:101 Error deleting folder: name 'shutil' is not defined
Traceback (most recent call last):
  File "c:/Agy/Programming/BelAInnovations/Projects/LLMFileManager/llm_file_operations/src/file_operations.py", line 96, in delete_folder
    shutil.rmtree(folder_path)
    ^^^^^^
NameError: name 'shutil' is not defined
======================================================================== short test summary info =========================================================================
FAILED src/file_operations_unit_test.py::test_create_file - AssertionError: Expected 'write' to be called once. Called 0 times.
FAILED src/file_operations_unit_test.py::test_modify_file_replace - AttributeError: __enter__
FAILED src/file_operations_unit_test.py::test_modify_file_insert - AttributeError: __enter__
FAILED src/file_operations_unit_test.py::test_execute_file_size_limit - AssertionError: expected call not found.
FAILED src/file_operations_unit_test.py::test_modify_file_delete - AttributeError: __enter__
FAILED src/file_operations_unit_test.py::test_delete_folder - AssertionError: Expected 'rmtree' to be called once. Called 0 times.
====================================================================== 6 failed, 42 passed in 1.85s ======================================================================

Exit Code: 1

================================================================================

## Test Run 5

### Test Results

========================================================================== test session starts ===========================================================================
platform win32 -- Python 3.11.4, pytest-8.2.2, pluggy-1.5.0 -- C:/ProgramData/anaconda3/envs/AG_Ex1/python.exe
cachedir: .pytest_cache
rootdir: c:/Agy/Programming/BelAInnovations/Projects/LLMFileManager/llm_file_operations
plugins: anyio-4.2.0
collecting ... collected 48 items

src/clipboard_monitor_unit_test.py::test_clipboard_monitor_initialization PASSED                                                                                    [  2%]
src/clipboard_monitor_unit_test.py::test_detect_format[LLMOP:/n  version: '1.0'-yaml] PASSED                                                                        [  4%]
src/clipboard_monitor_unit_test.py::test_detect_format[###LLMOP_START###/nSome content-custom] PASSED                                                               [  6%]
src/clipboard_monitor_unit_test.py::test_detect_format[Invalid content-None] PASSED                                                                                 [  8%]
src/clipboard_monitor_unit_test.py::test_start_monitoring_new_content PASSED                                                                                        [ 10%]
src/clipboard_monitor_unit_test.py::test_start_monitoring_error_handling PASSED                                                                                     [ 12%]
src/context_matcher_unit_test.py::test_initialization PASSED                                                                                                        [ 14%]
src/context_matcher_unit_test.py::test_find_context_lines_valid_contexts PASSED                                                                                     [ 16%]
src/context_matcher_unit_test.py::test_find_context_lines_start_only PASSED                                                                                         [ 18%]
src/context_matcher_unit_test.py::test_find_context_lines_no_contexts PASSED                                                                                        [ 20%]
src/context_matcher_unit_test.py::test_find_context_lines_start_not_found PASSED                                                                                    [ 22%]
src/context_matcher_unit_test.py::test_find_context_lines_end_not_found PASSED                                                                                      [ 25%]
src/context_matcher_unit_test.py::test_find_context_lines_multiline_contexts PASSED                                                                                 [ 27%]
src/context_matcher_unit_test.py::test_find_context_lines_beginning_of_file PASSED                                                                                  [ 29%]
src/context_matcher_unit_test.py::test_find_context_lines_end_of_file PASSED                                                                                        [ 31%]
src/context_matcher_unit_test.py::test_find_context_lines_overlapping_contexts PASSED                                                                               [ 33%]
src/context_matcher_unit_test.py::test_find_start_context PASSED                                                                                                    [ 35%]
src/context_matcher_unit_test.py::test_find_end_context PASSED                                                                                                      [ 37%]
src/context_matcher_unit_test.py::test_whitespace_handling PASSED                                                                                                   [ 39%]
src/context_matcher_unit_test.py::test_performance_large_files[100] PASSED                                                                                          [ 41%]
src/context_matcher_unit_test.py::test_performance_large_files[1000] PASSED                                                                                         [ 43%]
src/context_matcher_unit_test.py::test_performance_large_files[10000] PASSED                                                                                        [ 45%]
src/error_handler_unit_test.py::test_error_handler_initialization PASSED                                                                                            [ 47%]
src/error_handler_unit_test.py::test_handle_standard_exception PASSED                                                                                               [ 50%]
src/error_handler_unit_test.py::test_handle_custom_exception PASSED                                                                                                 [ 52%]
src/error_handler_unit_test.py::test_handle_system_exception PASSED                                                                                                 [ 54%]
src/error_handler_unit_test.py::test_handle_error_simple_message PASSED                                                                                             [ 56%]
src/error_handler_unit_test.py::test_handle_error_multiline_message PASSED                                                                                          [ 58%]
src/error_handler_unit_test.py::test_handle_error_special_characters PASSED                                                                                         [ 60%]
src/error_handler_unit_test.py::test_logging_level PASSED                                                                                                           [ 62%]
src/error_handler_unit_test.py::test_exception_and_traceback_logged PASSED                                                                                          [ 64%]
src/error_handler_unit_test.py::test_logging_behavior_different_levels[DEBUG] PASSED                                                                                [ 66%]
src/error_handler_unit_test.py::test_logging_behavior_different_levels[INFO] PASSED                                                                                 [ 68%]
src/error_handler_unit_test.py::test_logging_behavior_different_levels[WARNING] PASSED                                                                              [ 70%]
src/error_handler_unit_test.py::test_logging_behavior_different_levels[ERROR] PASSED                                                                                [ 72%]
src/error_handler_unit_test.py::test_logging_behavior_different_levels[CRITICAL] PASSED                                                                             [ 75%]
src/file_operations_unit_test.py::test_create_file FAILED                                                                                                           [ 77%]
src/file_operations_unit_test.py::test_create_folder PASSED                                                                                                         [ 79%]
src/file_operations_unit_test.py::test_delete_file PASSED                                                                                                           [ 81%]
src/file_operations_unit_test.py::test_modify_file_replace FAILED                                                                                                   [ 83%]
src/file_operations_unit_test.py::test_modify_file_insert FAILED                                                                                                    [ 85%]
src/file_operations_unit_test.py::test_execute_file_size_limit FAILED                                                                                               [ 87%]
src/file_operations_unit_test.py::test_execute_invalid_file_extension PASSED                                                                                        [ 89%]
src/file_operations_unit_test.py::test_delete_nonexistent_file PASSED                                                                                               [ 91%]
src/file_operations_unit_test.py::test_create_folder_permission_error PASSED                                                                                        [ 93%]
src/file_operations_unit_test.py::test_execute_unknown_action PASSED                                                                                                [ 95%]
src/file_operations_unit_test.py::test_modify_file_delete FAILED                                                                                                    [ 97%]
src/file_operations_unit_test.py::test_delete_folder FAILED                                                                                                         [100%]

================================================================================ FAILURES ================================================================================
____________________________________________________________________________ test_create_file ____________________________________________________________________________
src/file_operations_unit_test.py:35: in test_create_file
    mock_open().write.assert_called_once_with('content')
C:/ProgramData/anaconda3/envs/AG_Ex1/Lib/unittest/mock.py:950: in assert_called_once_with
    raise AssertionError(msg)
E   AssertionError: Expected 'write' to be called once. Called 0 times.
--------------------------------------------------------------------------- Captured log call ----------------------------------------------------------------------------
ERROR    file_operations:file_operations.py:67 Error creating file: 'Mock' object does not support the context manager protocol
Traceback (most recent call last):
  File "c:/Agy/Programming/BelAInnovations/Projects/LLMFileManager/llm_file_operations/src/file_operations.py", line 60, in create_file
    with open(file_path, 'w', newline='') as f:
TypeError: 'Mock' object does not support the context manager protocol
________________________________________________________________________ test_modify_file_replace ________________________________________________________________________
src/file_operations_unit_test.py:52: in test_modify_file_replace
    mock_open.return_value.__enter__.return_value.readlines.return_value = mock_file_content
C:/ProgramData/anaconda3/envs/AG_Ex1/Lib/unittest/mock.py:655: in __getattr__
    raise AttributeError(name)
E   AttributeError: __enter__
________________________________________________________________________ test_modify_file_insert _________________________________________________________________________
src/file_operations_unit_test.py:72: in test_modify_file_insert
    mock_open.return_value.__enter__.return_value.readlines.return_value = mock_file_content
C:/ProgramData/anaconda3/envs/AG_Ex1/Lib/unittest/mock.py:655: in __getattr__
    raise AttributeError(name)
E   AttributeError: __enter__
______________________________________________________________________ test_execute_file_size_limit ______________________________________________________________________
src/file_operations_unit_test.py:100: in test_execute_file_size_limit
    mock_error_handler.handle_error.assert_called_once_with("File size exceeds maximum allowed size: large_file.txt")
C:/ProgramData/anaconda3/envs/AG_Ex1/Lib/unittest/mock.py:951: in assert_called_once_with
    return self.assert_called_with(*args, **kwargs)
C:/ProgramData/anaconda3/envs/AG_Ex1/Lib/unittest/mock.py:939: in assert_called_with
    raise AssertionError(_error_message()) from cause
E   AssertionError: expected call not found.
E   Expected: handle_error('File size exceeds maximum allowed size: large_file.txt')
E   Actual: handle_error('File size exceeds maximum allowed size: .//large_file.txt')
________________________________________________________________________ test_modify_file_delete _________________________________________________________________________
src/file_operations_unit_test.py:134: in test_modify_file_delete
    mock_open.return_value.__enter__.return_value.readlines.return_value = mock_file_content
C:/ProgramData/anaconda3/envs/AG_Ex1/Lib/unittest/mock.py:655: in __getattr__
    raise AttributeError(name)
E   AttributeError: __enter__
___________________________________________________________________________ test_delete_folder ___________________________________________________________________________
src/file_operations_unit_test.py:154: in test_delete_folder
    mock_rmtree.assert_called_once_with('test/folder')
C:/ProgramData/anaconda3/envs/AG_Ex1/Lib/unittest/mock.py:950: in assert_called_once_with
    raise AssertionError(msg)
E   AssertionError: Expected 'rmtree' to be called once. Called 0 times.
--------------------------------------------------------------------------- Captured log call ----------------------------------------------------------------------------
ERROR    file_operations:file_operations.py:101 Error deleting folder: name 'shutil' is not defined
Traceback (most recent call last):
  File "c:/Agy/Programming/BelAInnovations/Projects/LLMFileManager/llm_file_operations/src/file_operations.py", line 96, in delete_folder
    shutil.rmtree(folder_path)
    ^^^^^^
NameError: name 'shutil' is not defined
======================================================================== short test summary info =========================================================================
FAILED src/file_operations_unit_test.py::test_create_file - AssertionError: Expected 'write' to be called once. Called 0 times.
FAILED src/file_operations_unit_test.py::test_modify_file_replace - AttributeError: __enter__
FAILED src/file_operations_unit_test.py::test_modify_file_insert - AttributeError: __enter__
FAILED src/file_operations_unit_test.py::test_execute_file_size_limit - AssertionError: expected call not found.
FAILED src/file_operations_unit_test.py::test_modify_file_delete - AttributeError: __enter__
FAILED src/file_operations_unit_test.py::test_delete_folder - AssertionError: Expected 'rmtree' to be called once. Called 0 times.
====================================================================== 6 failed, 42 passed in 1.74s ======================================================================

Exit Code: 1

================================================================================

